 * Serving Flask app "app" (lazy loading)
 * Environment: production
   WARNING: This is a development server. Do not use it in a production deployment.
   Use a production WSGI server instead.
 * Debug mode: off
Traceback (most recent call last):
  File "app.py", line 25, in <module>
    app.run(host='0.0.0.0', port=9290)
  File "/home/marcosscharipa/Documents/UBA/Trabajo Profesional/eleccionesFrontEnd/Mini-BackEnd/venv/lib/python3.6/site-packages/flask/app.py", line 944, in run
    run_simple(host, port, self, **options)
  File "/home/marcosscharipa/Documents/UBA/Trabajo Profesional/eleccionesFrontEnd/Mini-BackEnd/venv/lib/python3.6/site-packages/werkzeug/serving.py", line 1009, in run_simple
    inner()
  File "/home/marcosscharipa/Documents/UBA/Trabajo Profesional/eleccionesFrontEnd/Mini-BackEnd/venv/lib/python3.6/site-packages/werkzeug/serving.py", line 962, in inner
    fd=fd,
  File "/home/marcosscharipa/Documents/UBA/Trabajo Profesional/eleccionesFrontEnd/Mini-BackEnd/venv/lib/python3.6/site-packages/werkzeug/serving.py", line 805, in make_server
    host, port, app, request_handler, passthrough_errors, ssl_context, fd=fd
  File "/home/marcosscharipa/Documents/UBA/Trabajo Profesional/eleccionesFrontEnd/Mini-BackEnd/venv/lib/python3.6/site-packages/werkzeug/serving.py", line 698, in __init__
    HTTPServer.__init__(self, server_address, handler)
  File "/usr/lib/python3.6/socketserver.py", line 453, in __init__
    self.server_bind()
  File "/usr/lib/python3.6/http/server.py", line 136, in server_bind
    socketserver.TCPServer.server_bind(self)
  File "/usr/lib/python3.6/socketserver.py", line 467, in server_bind
    self.socket.bind(self.server_address)
OSError: [Errno 98] Address already in use
 * Serving Flask app "app" (lazy loading)
 * Environment: production
   WARNING: This is a development server. Do not use it in a production deployment.
   Use a production WSGI server instead.
 * Debug mode: off
 * Running on http://0.0.0.0:9290/ (Press CTRL+C to quit)
127.0.0.1 - - [27/Jun/2019 17:57:41] "GET /candidates HTTP/1.1" 200 -
 * Serving Flask app "app" (lazy loading)
 * Environment: production
   WARNING: This is a development server. Do not use it in a production deployment.
   Use a production WSGI server instead.
 * Debug mode: off
Traceback (most recent call last):
  File "app.py", line 23, in <module>
    app.run(host='0.0.0.0', port=9290)
  File "/home/marcosscharipa/Documents/UBA/Trabajo Profesional/eleccionesFrontEnd/Mini-BackEnd/venv/lib/python3.6/site-packages/flask/app.py", line 944, in run
    run_simple(host, port, self, **options)
  File "/home/marcosscharipa/Documents/UBA/Trabajo Profesional/eleccionesFrontEnd/Mini-BackEnd/venv/lib/python3.6/site-packages/werkzeug/serving.py", line 1009, in run_simple
    inner()
  File "/home/marcosscharipa/Documents/UBA/Trabajo Profesional/eleccionesFrontEnd/Mini-BackEnd/venv/lib/python3.6/site-packages/werkzeug/serving.py", line 962, in inner
    fd=fd,
  File "/home/marcosscharipa/Documents/UBA/Trabajo Profesional/eleccionesFrontEnd/Mini-BackEnd/venv/lib/python3.6/site-packages/werkzeug/serving.py", line 805, in make_server
    host, port, app, request_handler, passthrough_errors, ssl_context, fd=fd
  File "/home/marcosscharipa/Documents/UBA/Trabajo Profesional/eleccionesFrontEnd/Mini-BackEnd/venv/lib/python3.6/site-packages/werkzeug/serving.py", line 698, in __init__
    HTTPServer.__init__(self, server_address, handler)
  File "/usr/lib/python3.6/socketserver.py", line 453, in __init__
    self.server_bind()
  File "/usr/lib/python3.6/http/server.py", line 136, in server_bind
    socketserver.TCPServer.server_bind(self)
  File "/usr/lib/python3.6/socketserver.py", line 467, in server_bind
    self.socket.bind(self.server_address)
OSError: [Errno 98] Address already in use
 * Serving Flask app "app" (lazy loading)
 * Environment: production
   WARNING: This is a development server. Do not use it in a production deployment.
   Use a production WSGI server instead.
 * Debug mode: off
 * Running on http://0.0.0.0:9290/ (Press CTRL+C to quit)
[2019-06-27 17:58:36,362] ERROR in app: Exception on /candidates [GET]
Traceback (most recent call last):
  File "/home/marcosscharipa/Documents/UBA/Trabajo Profesional/eleccionesFrontEnd/Mini-BackEnd/venv/lib/python3.6/site-packages/flask/app.py", line 1993, in make_response
    rv = self.response_class.force_type(rv, request.environ)
  File "/home/marcosscharipa/Documents/UBA/Trabajo Profesional/eleccionesFrontEnd/Mini-BackEnd/venv/lib/python3.6/site-packages/werkzeug/wrappers/base_response.py", line 269, in force_type
    response = BaseResponse(*_run_wsgi_app(response, environ))
  File "/home/marcosscharipa/Documents/UBA/Trabajo Profesional/eleccionesFrontEnd/Mini-BackEnd/venv/lib/python3.6/site-packages/werkzeug/wrappers/base_response.py", line 26, in _run_wsgi_app
    return _run_wsgi_app(*args)
  File "/home/marcosscharipa/Documents/UBA/Trabajo Profesional/eleccionesFrontEnd/Mini-BackEnd/venv/lib/python3.6/site-packages/werkzeug/test.py", line 1119, in run_wsgi_app
    app_rv = app(environ, start_response)
TypeError: 'list' object is not callable

During handling of the above exception, another exception occurred:

Traceback (most recent call last):
  File "/home/marcosscharipa/Documents/UBA/Trabajo Profesional/eleccionesFrontEnd/Mini-BackEnd/venv/lib/python3.6/site-packages/flask/app.py", line 2311, in wsgi_app
    response = self.full_dispatch_request()
  File "/home/marcosscharipa/Documents/UBA/Trabajo Profesional/eleccionesFrontEnd/Mini-BackEnd/venv/lib/python3.6/site-packages/flask/app.py", line 1835, in full_dispatch_request
    return self.finalize_request(rv)
  File "/home/marcosscharipa/Documents/UBA/Trabajo Profesional/eleccionesFrontEnd/Mini-BackEnd/venv/lib/python3.6/site-packages/flask/app.py", line 1850, in finalize_request
    response = self.make_response(rv)
  File "/home/marcosscharipa/Documents/UBA/Trabajo Profesional/eleccionesFrontEnd/Mini-BackEnd/venv/lib/python3.6/site-packages/flask/app.py", line 2001, in make_response
    reraise(TypeError, new_error, sys.exc_info()[2])
  File "/home/marcosscharipa/Documents/UBA/Trabajo Profesional/eleccionesFrontEnd/Mini-BackEnd/venv/lib/python3.6/site-packages/flask/_compat.py", line 35, in reraise
    raise value.with_traceback(tb)
  File "/home/marcosscharipa/Documents/UBA/Trabajo Profesional/eleccionesFrontEnd/Mini-BackEnd/venv/lib/python3.6/site-packages/flask/app.py", line 1993, in make_response
    rv = self.response_class.force_type(rv, request.environ)
  File "/home/marcosscharipa/Documents/UBA/Trabajo Profesional/eleccionesFrontEnd/Mini-BackEnd/venv/lib/python3.6/site-packages/werkzeug/wrappers/base_response.py", line 269, in force_type
    response = BaseResponse(*_run_wsgi_app(response, environ))
  File "/home/marcosscharipa/Documents/UBA/Trabajo Profesional/eleccionesFrontEnd/Mini-BackEnd/venv/lib/python3.6/site-packages/werkzeug/wrappers/base_response.py", line 26, in _run_wsgi_app
    return _run_wsgi_app(*args)
  File "/home/marcosscharipa/Documents/UBA/Trabajo Profesional/eleccionesFrontEnd/Mini-BackEnd/venv/lib/python3.6/site-packages/werkzeug/test.py", line 1119, in run_wsgi_app
    app_rv = app(environ, start_response)
TypeError: 'list' object is not callable
The view function did not return a valid response. The return type must be a string, tuple, Response instance, or WSGI callable, but it was a list.
127.0.0.1 - - [27/Jun/2019 17:58:36] "GET /candidates HTTP/1.1" 500 -
 * Serving Flask app "app" (lazy loading)
 * Environment: production
   WARNING: This is a development server. Do not use it in a production deployment.
   Use a production WSGI server instead.
 * Debug mode: off
 * Running on http://0.0.0.0:9290/ (Press CTRL+C to quit)
[2019-06-27 17:59:03,355] ERROR in app: Exception on /candidates [GET]
Traceback (most recent call last):
  File "/home/marcosscharipa/Documents/UBA/Trabajo Profesional/eleccionesFrontEnd/Mini-BackEnd/venv/lib/python3.6/site-packages/flask/app.py", line 2311, in wsgi_app
    response = self.full_dispatch_request()
  File "/home/marcosscharipa/Documents/UBA/Trabajo Profesional/eleccionesFrontEnd/Mini-BackEnd/venv/lib/python3.6/site-packages/flask/app.py", line 1834, in full_dispatch_request
    rv = self.handle_user_exception(e)
  File "/home/marcosscharipa/Documents/UBA/Trabajo Profesional/eleccionesFrontEnd/Mini-BackEnd/venv/lib/python3.6/site-packages/flask/app.py", line 1737, in handle_user_exception
    reraise(exc_type, exc_value, tb)
  File "/home/marcosscharipa/Documents/UBA/Trabajo Profesional/eleccionesFrontEnd/Mini-BackEnd/venv/lib/python3.6/site-packages/flask/_compat.py", line 36, in reraise
    raise value
  File "/home/marcosscharipa/Documents/UBA/Trabajo Profesional/eleccionesFrontEnd/Mini-BackEnd/venv/lib/python3.6/site-packages/flask/app.py", line 1832, in full_dispatch_request
    rv = self.dispatch_request()
  File "/home/marcosscharipa/Documents/UBA/Trabajo Profesional/eleccionesFrontEnd/Mini-BackEnd/venv/lib/python3.6/site-packages/flask/app.py", line 1818, in dispatch_request
    return self.view_functions[rule.endpoint](**req.view_args)
  File "app.py", line 15, in candidates
    return candidatesData.text()
TypeError: 'str' object is not callable
127.0.0.1 - - [27/Jun/2019 17:59:03] "GET /candidates HTTP/1.1" 500 -
 * Serving Flask app "app" (lazy loading)
 * Environment: production
   WARNING: This is a development server. Do not use it in a production deployment.
   Use a production WSGI server instead.
 * Debug mode: off
 * Running on http://0.0.0.0:9290/ (Press CTRL+C to quit)
127.0.0.1 - - [27/Jun/2019 17:59:23] "GET /candidates HTTP/1.1" 200 -
